Workbook

Sheet Grafik
K1: ANA GÖREV | N1: YAN GÖREV
K2: =VLOOKUP($E$5,'Personel Görev Dağılım'!A:D,2,0) -> YARI MAMUL MONTAJ | N2: =VLOOKUP($E$5,'Personel Görev Dağılım'!A:D,3,0) -> OSB YARI MAMUL MONTAJ
B4: PERSONEL SEÇ | E4: =VLOOKUP($E$5,'Menü Seçenekleri'!F7:G21,2,0) -> EMİR KODAŞ (H)
E5: EMİR KODAŞ
K6: HEDEF BAŞARI PUANI | N6: GERÇEKLEŞEN BAŞARI PUANI | Q6: BAŞARI ORANI
K7: ='Grafik Verileri'!B164 -> 705 | N7: ='Grafik Verileri'!C164 -> 547 | Q7: =N7/K7 -> 0.77588652

Sheet Grafik Verileri
A1: YAPILAN İŞLEM | B1: PERSONEL HEDEF PUANI | C1: PERSONEL GERÇEKLEŞEN PUANI
A2: AER-1 MONTAJ HATTI 1 | B2: =HLOOKUP(Grafik!$E$4,'Tüm Operasyonlar'!$D$1:$AG$164,3,0) -> - | C2: =HLOOKUP(Grafik!$E$5,'Tüm Operasyonlar'!$D$1:$AG$164,3,0) -> -
A3: AER-1 MONTAJ HATTI 2 | B3: =HLOOKUP(Grafik!$E$4,'Tüm Operasyonlar'!$D$1:$AG$164,4,0) -> - | C3: =HLOOKUP(Grafik!$E$5,'Tüm Operasyonlar'!$D$1:$AG$164,4,0) -> -
A4: AER-1 MONTAJ HATTI 3 | B4: =HLOOKUP(Grafik!$E$4,'Tüm Operasyonlar'!$D$1:$AG$164,5,0) -> - | C4: =HLOOKUP(Grafik!$E$5,'Tüm Operasyonlar'!$D$1:$AG$164,5,0) -> -
A5: AER-1 MONTAJ HATTI 4 | B5: =HLOOKUP(Grafik!$E$4,'Tüm Operasyonlar'!$D$1:$AG$164,6,0) -> - | C5: =HLOOKUP(Grafik!$E$5,'Tüm Operasyonlar'!$D$1:$AG$164,6,0) -> -
A6: AER-1 5 YIKAMA HAZIRLIK | B6: =HLOOKUP(Grafik!$E$4,'Tüm Operasyonlar'!$D$1:$AG$164,7,0) -> - | C6: =HLOOKUP(Grafik!$E$5,'Tüm Operasyonlar'!$D$1:$AG$164,7,0) -> -
A7: AER-1 YIKAMA HATTI REWORK | B7: =HLOOKUP(Grafik!$E$4,'Tüm Operasyonlar'!$D$1:$AG$164,8,0) -> - | C7: =HLOOKUP(Grafik!$E$5,'Tüm Operasyonlar'!$D$1:$AG$164,8,0) -> -
A8: AER-1 TEMİZLİK HATTI | B8: =HLOOKUP(Grafik!$E$4,'Tüm Operasyonlar'!$D$1:$AG$164,9,0) -> - | C8: =HLOOKUP(Grafik!$E$5,'Tüm Operasyonlar'!$D$1:$AG$164,9,0) -> -
A9: AER-1 PAKET ÖNCESİ HAZIRLIK | B9: =HLOOKUP(Grafik!$E$4,'Tüm Operasyonlar'!$D$1:$AG$164,10,0) -> - | C9: =HLOOKUP(Grafik!$E$5,'Tüm Operasyonlar'!$D$1:$AG$164,10,0) -> -
A10: AER-1 PAKETLEME OPERASYONU | B10: =HLOOKUP(Grafik!$E$4,'Tüm Operasyonlar'!$D$1:$AG$164,11,0) -> - | C10: =HLOOKUP(Grafik!$E$5,'Tüm Operasyonlar'!$D$1:$AG$164,11,0) -> -
A11: CPC ERKEK 90° | B11: =HLOOKUP(Grafik!$E$4,'Tüm Operasyonlar'!$D$1:$AG$164,12,0) -> 5 | C11: =HLOOKUP(Grafik!$E$5,'Tüm Operasyonlar'!$D$1:$AG$164,12,0) -> 5
A12: DIŞ FİLTRE GRUBU | B12: =HLOOKUP(Grafik!$E$4,'Tüm Operasyonlar'!$D$1:$AG$164,13,0) -> 5 | C12: =HLOOKUP(Grafik!$E$5,'Tüm Operasyonlar'!$D$1:$AG$164,13,0) -> 4
A13: CPC DAĞITICI-ÇİFT SKOP GRUBU | B13: =HLOOKUP(Grafik!$E$4,'Tüm Operasyonlar'!$D$1:$AG$164,14,0) -> 5 | C13: =HLOOKUP(Grafik!$E$5,'Tüm Operasyonlar'!$D$1:$AG$164,14,0) -> 5
A14: NOZZLE DAĞITICI GRUBU | B14: =HLOOKUP(Grafik!$E$4,'Tüm Operasyonlar'!$D$1:$AG$164,15,0) -> 5 | C14: =HLOOKUP(Grafik!$E$5,'Tüm Operasyonlar'!$D$1:$AG$164,15,0) -> 5
A15: DOLUM KAPAK GRUBU-ALKOL | B15: =HLOOKUP(Grafik!$E$4,'Tüm Operasyonlar'!$D$1:$AG$164,16,0) -> 5 | C15: =HLOOKUP(Grafik!$E$5,'Tüm Operasyonlar'!$D$1:$AG$164,16,0) -> 5
A16: DOLUM KAPAK GRUBU-ENZIMATIK | B16: =HLOOKUP(Grafik!$E$4,'Tüm Operasyonlar'!$D$1:$AG$164,17,0) -> 5 | C16: =HLOOKUP(Grafik!$E$5,'Tüm Operasyonlar'!$D$1:$AG$164,17,0) -> 5
A17: DOLUM KAPAK GRUBU-KONSANTRE | B17: =HLOOKUP(Grafik!$E$4,'Tüm Operasyonlar'!$D$1:$AG$164,18,0) -> 5 | C17: =HLOOKUP(Grafik!$E$5,'Tüm Operasyonlar'!$D$1:$AG$164,18,0) -> 5
A18: 5 L KONS. DEZ. DEPO GRUBU | B18: =HLOOKUP(Grafik!$E$4,'Tüm Operasyonlar'!$D$1:$AG$164,19,0) -> 5 | C18: =HLOOKUP(Grafik!$E$5,'Tüm Operasyonlar'!$D$1:$AG$164,19,0) -> 2
A19: 5 L ENZİM DEPO GRUBU | B19: =HLOOKUP(Grafik!$E$4,'Tüm Operasyonlar'!$D$1:$AG$164,20,0) -> 5 | C19: =HLOOKUP(Grafik!$E$5,'Tüm Operasyonlar'!$D$1:$AG$164,20,0) -> 2
A20: 5 L ALKOL DEPO GRUBU | B20: =HLOOKUP(Grafik!$E$4,'Tüm Operasyonlar'!$D$1:$AG$164,21,0) -> 5 | C20: =HLOOKUP(Grafik!$E$5,'Tüm Operasyonlar'!$D$1:$AG$164,21,0) -> 2
A21: 15 L ATIK DEPO GRUBU | B21: =HLOOKUP(Grafik!$E$4,'Tüm Operasyonlar'!$D$1:$AG$164,22,0) -> 5 | C21: =HLOOKUP(Grafik!$E$5,'Tüm Operasyonlar'!$D$1:$AG$164,22,0) -> 2
A22: 15 L DEZENFEKTAN DEPO GRUBU | B22: =HLOOKUP(Grafik!$E$4,'Tüm Operasyonlar'!$D$1:$AG$164,23,0) -> 5 | C22: =HLOOKUP(Grafik!$E$5,'Tüm Operasyonlar'!$D$1:$AG$164,23,0) -> 2
A23: 15 L TEMİZ SU DEPO GRUBU | B23: =HLOOKUP(Grafik!$E$4,'Tüm Operasyonlar'!$D$1:$AG$164,24,0) -> 5 | C23: =HLOOKUP(Grafik!$E$5,'Tüm Operasyonlar'!$D$1:$AG$164,24,0) -> 2
A24: 15 L PASLANMAZ DEPO GRUBU | B24: =HLOOKUP(Grafik!$E$4,'Tüm Operasyonlar'!$D$1:$AG$164,25,0) -> 5 | C24: =HLOOKUP(Grafik!$E$5,'Tüm Operasyonlar'!$D$1:$AG$164,25,0) -> 2
A25: DOZAJ POMPA GRUBU 7 L | B25: =HLOOKUP(Grafik!$E$4,'Tüm Operasyonlar'!$D$1:$AG$164,26,0) -> 5 | C25: =HLOOKUP(Grafik!$E$5,'Tüm Operasyonlar'!$D$1:$AG$164,26,0) -> 5
A26: 70X100 TANITIM PLAKASI | B26: =HLOOKUP(Grafik!$E$4,'Tüm Operasyonlar'!$D$1:$AG$164,27,0) -> 5 | C26: =HLOOKUP(Grafik!$E$5,'Tüm Operasyonlar'!$D$1:$AG$164,27,0) -> 3
A27: GİRDAP ÖNLEYİCİ | B27: =HLOOKUP(Grafik!$E$4,'Tüm Operasyonlar'!$D$1:$AG$164,28,0) -> 5 | C27: =HLOOKUP(Grafik!$E$5,'Tüm Operasyonlar'!$D$1:$AG$164,28,0) -> 1
A28: EVYE-ÇİFT SKOP, ÇİFT TANK GRUBU | B28: =HLOOKUP(Grafik!$E$4,'Tüm Operasyonlar'!$D$1:$AG$164,29,0) -> 5 | C28: =HLOOKUP(Grafik!$E$5,'Tüm Operasyonlar'!$D$1:$AG$164,29,0) -> 1
A29: SELENOİD TEL FİLTRE GRUBU | B29: =HLOOKUP(Grafik!$E$4,'Tüm Operasyonlar'!$D$1:$AG$164,30,0) -> 5 | C29: =HLOOKUP(Grafik!$E$5,'Tüm Operasyonlar'!$D$1:$AG$164,30,0) -> 5
A30: EVYE GİDER GRUBU | B30: =HLOOKUP(Grafik!$E$4,'Tüm Operasyonlar'!$D$1:$AG$164,31,0) -> 5 | C30: =HLOOKUP(Grafik!$E$5,'Tüm Operasyonlar'!$D$1:$AG$164,31,0) -> 5
A31: KABLO SETİ-İLETİŞİM-USB KABLO GRUBU | B31: =HLOOKUP(Grafik!$E$4,'Tüm Operasyonlar'!$D$1:$AG$164,32,0) -> 5 | C31: =HLOOKUP(Grafik!$E$5,'Tüm Operasyonlar'!$D$1:$AG$164,32,0) -> 5
A32: OLF 100AF KOMPRESÖR GRUBU | B32: =HLOOKUP(Grafik!$E$4,'Tüm Operasyonlar'!$D$1:$AG$164,33,0) -> 5 | C32: =HLOOKUP(Grafik!$E$5,'Tüm Operasyonlar'!$D$1:$AG$164,33,0) -> 5
A33: AER 1 KOMPRESÖR SELENOİD VALF GRUBU | B33: =HLOOKUP(Grafik!$E$4,'Tüm Operasyonlar'!$D$1:$AG$164,34,0) -> 5 | C33: =HLOOKUP(Grafik!$E$5,'Tüm Operasyonlar'!$D$1:$AG$164,34,0) -> 5
A34: KAPAK GRUBU KİLİTSİZ MODEL | B34: =HLOOKUP(Grafik!$E$4,'Tüm Operasyonlar'!$D$1:$AG$164,35,0) -> 5 | C34: =HLOOKUP(Grafik!$E$5,'Tüm Operasyonlar'!$D$1:$AG$164,35,0) -> 1
A35: 15 L DEZENFEKTAN DEPO KAPAK GRUBU | B35: =HLOOKUP(Grafik!$E$4,'Tüm Operasyonlar'!$D$1:$AG$164,36,0) -> 5 | C35: =HLOOKUP(Grafik!$E$5,'Tüm Operasyonlar'!$D$1:$AG$164,36,0) -> 5
A36: 15 L ATIK DEPO KAPAK GRUBU | B36: =HLOOKUP(Grafik!$E$4,'Tüm Operasyonlar'!$D$1:$AG$164,37,0) -> 5 | C36: =HLOOKUP(Grafik!$E$5,'Tüm Operasyonlar'!$D$1:$AG$164,37,0) -> 5
A37: 15 L TEMİZ SU DEPO+UV KAPAK GRUBU | B37: =HLOOKUP(Grafik!$E$4,'Tüm Operasyonlar'!$D$1:$AG$164,38,0) -> 5 | C37: =HLOOKUP(Grafik!$E$5,'Tüm Operasyonlar'!$D$1:$AG$164,38,0) -> 5
A38: 5 L DEPO KAPAK GRUBU | B38: =HLOOKUP(Grafik!$E$4,'Tüm Operasyonlar'!$D$1:$AG$164,39,0) -> 5 | C38: =HLOOKUP(Grafik!$E$5,'Tüm Operasyonlar'!$D$1:$AG$164,39,0) -> 5
A39: 15 L PASLANMAZ DEPO KAPAK GRUBU | B39: =HLOOKUP(Grafik!$E$4,'Tüm Operasyonlar'!$D$1:$AG$164,40,0) -> 5 | C39: =HLOOKUP(Grafik!$E$5,'Tüm Operasyonlar'!$D$1:$AG$164,40,0) -> 5
A40: AER 1 ÜST KAPAK ARKA MENTEŞE GRUBU | B40: =HLOOKUP(Grafik!$E$4,'Tüm Operasyonlar'!$D$1:$AG$164,41,0) -> 5 | C40: =HLOOKUP(Grafik!$E$5,'Tüm Operasyonlar'!$D$1:$AG$164,41,0) -> 5
...

Sheet Tüm Operasyonlar
A1: SIRA NO | B1: CİHAZ | C1: STOK KODU | D1: STOK ADI | E1: ZORLUK DERECESİ | F1: İZZET ATAKAN DEMİR (H) | G1: İZZET ATAKAN DEMİR | H1: ÜMİT UZUN (H) | I1: ÜMİT UZUN | J1: TOLGAHAN ÇEBİ (H) | K1: TOLGAHAN ÇEBİ | L1: KAĞAN UDUM (H) | M1: KAĞAN UDUM | N1: OZAN HATAY (H) | O1: OZAN HATAY | P1: MURAT KİRAZ (H) | Q1: MURAT KİRAZ | R1: VOLKAN KAVLAK (H) | S1: VOLKAN KAVLAK | T1: MUSA HIZIR (H) | U1: MUSA HIZIR | V1: ÖZER KOÇ (H) | W1: ÖZER KOÇ | X1: ÖMER POLAT (H) | Y1: ÖMER POLAT | Z1: SEMRA ULTAV (H) | AA1: SEMRA ULTAV | AB1: HANDE GÜNAYDIN (H) | AC1: HANDE GÜNAYDIN | AD1: SULTAN SOLAK (H) | AE1: SULTAN SOLAK | AF1: EMİR KODAŞ (H) | AG1: EMİR KODAŞ
F2: HEDEF | G2: GERÇEKLEŞEN | H2: HEDEF | I2: GERÇEKLEŞEN | J2: HEDEF | K2: GERÇEKLEŞEN | L2: HEDEF | M2: GERÇEKLEŞEN | N2: HEDEF | O2: GERÇEKLEŞEN | P2: HEDEF | Q2: GERÇEKLEŞEN | R2: HEDEF | S2: GERÇEKLEŞEN | T2: HEDEF | U2: GERÇEKLEŞEN | V2: HEDEF | W2: GERÇEKLEŞEN | X2: HEDEF | Y2: GERÇEKLEŞEN | Z2: HEDEF | AA2: GERÇEKLEŞEN | AB2: HEDEF | AC2: GERÇEKLEŞEN | AD2: HEDEF | AE2: GERÇEKLEŞEN | AF2: HEDEF | AG2: GERÇEKLEŞEN
A3: 1 | B3: AER-1 | C3: AER-1 | D3: AER-1 MONTAJ HATTI 1 | E3: 4 | F3: 5 | G3: 4 | H3: 5 | I3: 2 | J3: 5 | K3: 5 | L3: 5 | M3: 5 | N3: - | O3: - | P3: 5 | Q3: 4 | R3: 5 | S3: 5 | T3: - | U3: - | V3: - | W3: - | X3: - | Y3: - | Z3: - | AA3: - | AB3: - | AC3: - | AD3: - | AE3: - | AF3: - | AG3: -
A4: 2 | B4: AER-1 | C4: AER-1 | D4: AER-1 MONTAJ HATTI 2 | E4: 4 | F4: 5 | G4: 4 | H4: 5 | I4: 2 | J4: 5 | K4: 5 | L4: 5 | M4: 5 | N4: - | O4: - | P4: 5 | Q4: 4 | R4: 5 | S4: 5 | T4: - | U4: - | V4: - | W4: - | X4: - | Y4: - | Z4: - | AA4: - | AB4: - | AC4: - | AD4: - | AE4: - | AF4: - | AG4: -
A5: 3 | B5: AER-1 | C5: AER-1 | D5: AER-1 MONTAJ HATTI 3 | E5: 5 | F5: 5 | G5: 4 | H5: 5 | I5: 1 | J5: 5 | K5: 5 | L5: 5 | M5: 3 | N5: - | O5: - | P5: 5 | Q5: 3 | R5: 5 | S5: 3 | T5: - | U5: - | V5: - | W5: - | X5: - | Y5: - | Z5: - | AA5: - | AB5: - | AC5: - | AD5: - | AE5: - | AF5: - | AG5: -
A6: 4 | B6: AER-1 | C6: AER-1 | D6: AER-1 MONTAJ HATTI 4 | E6: 5 | F6: 5 | G6: 4 | H6: 5 | I6: 1 | J6: 5 | K6: 5 | L6: 5 | M6: 5 | N6: - | O6: - | P6: 5 | Q6: 3 | R6: 5 | S6: 5 | T6: - | U6: - | V6: - | W6: - | X6: - | Y6: - | Z6: - | AA6: - | AB6: - | AC6: - | AD6: - | AE6: - | AF6: - | AG6: -
A7: 5 | B7: AER-1 | C7: AER-1 | D7: AER-1 5 YIKAMA HAZIRLIK | E7: 5 | F7: 5 | G7: 3 | H7: 5 | I7: 1 | J7: 5 | K7: 3 | L7: 5 | M7: 5 | N7: 5 | O7: 5 | P7: 5 | Q7: 3 | R7: 5 | S7: 5 | T7: - | U7: - | V7: - | W7: - | X7: - | Y7: - | Z7: - | AA7: - | AB7: - | AC7: - | AD7: - | AE7: - | AF7: - | AG7: -
A8: 6 | B8: AER-1 | C8: AER-1 | D8: AER-1 YIKAMA HATTI REWORK | E8: 5 | F8: 5 | G8: 5 | H8: 5 | I8: 1 | J8: 5 | K8: 5 | L8: 5 | M8: 5 | N8: 5 | O8: 3 | P8: 5 | Q8: 3 | R8: 5 | S8: 5 | T8: - | U8: - | V8: - | W8: - | X8: - | Y8: - | Z8: - | AA8: - | AB8: - | AC8: - | AD8: - | AE8: - | AF8: - | AG8: -
A9: 7 | B9: AER-1 | C9: AER-1 | D9: AER-1 TEMİZLİK HATTI | E9: 2 | F9: 5 | G9: 3 | H9: 5 | I9: 1 | J9: 5 | K9: 3 | L9: 5 | M9: 3 | N9: 5 | O9: 3 | P9: 5 | Q9: 3 | R9: 5 | S9: 3 | T9: - | U9: - | V9: - | W9: - | X9: - | Y9: - | Z9: - | AA9: - | AB9: 5 | AC9: 5 | AD9: - | AE9: - | AF9: - | AG9: -
A10: 8 | B10: AER-1 | C10: AER-1 | D10: AER-1 PAKET ÖNCESİ HAZIRLIK | E10: 4 | F10: 5 | G10: 3 | H10: 5 | I10: 1 | J10: 5 | K10: 3 | L10: 5 | M10: 5 | N10: 5 | O10: 3 | P10: 5 | Q10: 2 | R10: 5 | S10: 5 | T10: - | U10: - | V10: - | W10: - | X10: - | Y10: - | Z10: - | AA10: - | AB10: - | AC10: - | AD10: - | AE10: - | AF10: - | AG10: -
A11: 9 | B11: AER-1 | C11: AER-1 | D11: AER-1 PAKETLEME OPERASYONU | E11: 3 | F11: 5 | G11: 5 | H11: 5 | I11: 2 | J11: 5 | K11: 5 | L11: 5 | M11: 5 | N11: 5 | O11: 3 | P11: 5 | Q11: 5 | R11: 5 | S11: 5 | T11: - | U11: - | V11: - | W11: - | X11: - | Y11: - | Z11: - | AA11: - | AB11: - | AC11: - | AD11: - | AE11: - | AF11: - | AG11: -
A12: 10 | B12: AER-1 | C12: M-Y-DC.001 | D12: CPC ERKEK 90° | E12: 2 | F12: - | G12: - | H12: - | I12: - | J12: - | K12: - | L12: - | M12: - | N12: - | O12: - | P12: - | Q12: - | R12: - | S12: - | T12: 5 | U12: 5 | V12: 5 | W12: 5 | X12: 5 | Y12: 5 | Z12: 5 | AA12: 5 | AB12: 5 | AC12: 5 | AD12: 5 | AE12: 5 | AF12: 5 | AG12: 5
A13: 11 | B13: AER-1 | C13: M-Y-DF.001 | D13: DIŞ FİLTRE GRUBU | E13: 5 | F13: - | G13: - | H13: - | I13: - | J13: - | K13: - | L13: - | M13: - | N13: - | O13: - | P13: - | Q13: - | R13: - | S13: - | T13: 5 | U13: 5 | V13: 5 | W13: 5 | X13: 5 | Y13: 5 | Z13: 5 | AA13: 5 | AB13: 5 | AC13: 2 | AD13: 5 | AE13: 2 | AF13: 5 | AG13: 4
A14: 12 | B14: AER-1 | C14: M-Y-DG.001 | D14: CPC DAĞITICI-ÇİFT SKOP GRUBU | E14: 5 | F14: - | G14: - | H14: - | I14: - | J14: - | K14: - | L14: - | M14: - | N14: - | O14: - | P14: - | Q14: - | R14: - | S14: - | T14: 5 | U14: 5 | V14: 5 | W14: 5 | X14: 5 | Y14: 5 | Z14: 5 | AA14: 5 | AB14: 5 | AC14: 3 | AD14: 5 | AE14: 2 | AF14: 5 | AG14: 5
A15: 13 | B15: AER-1 | C15: M-Y-DG.002 | D15: NOZZLE DAĞITICI GRUBU | E15: 5 | F15: - | G15: - | H15: - | I15: - | J15: - | K15: - | L15: - | M15: - | N15: - | O15: - | P15: - | Q15: - | R15: - | S15: - | T15: 5 | U15: 5 | V15: 5 | W15: 5 | X15: 5 | Y15: 5 | Z15: 5 | AA15: 5 | AB15: 5 | AC15: 3 | AD15: 5 | AE15: 2 | AF15: 5 | AG15: 5
A16: 14 | B16: AER-1 | C16: M-Y-DK.001 | D16: DOLUM KAPAK GRUBU-ALKOL | E16: 2 | F16: - | G16: - | H16: - | I16: - | J16: - | K16: - | L16: - | M16: - | N16: - | O16: - | P16: - | Q16: - | R16: - | S16: - | T16: 5 | U16: 5 | V16: 5 | W16: 5 | X16: 5 | Y16: 5 | Z16: 5 | AA16: 5 | AB16: 5 | AC16: 5 | AD16: 5 | AE16: 4 | AF16: 5 | AG16: 5
A17: 15 | B17: AER-1 | C17: M-Y-DK.003 | D17: DOLUM KAPAK GRUBU-ENZIMATIK | E17: 2 | F17: - | G17: - | H17: - | I17: - | J17: - | K17: - | L17: - | M17: - | N17: - | O17: - | P17: - | Q17: - | R17: - | S17: - | T17: 5 | U17: 5 | V17: 5 | W17: 5 | X17: 5 | Y17: 5 | Z17: 5 | AA17: 5 | AB17: 5 | AC17: 5 | AD17: 5 | AE17: 4 | AF17: 5 | AG17: 5
A18: 16 | B18: AER-1 | C18: M-Y-DK.004 | D18: DOLUM KAPAK GRUBU-KONSANTRE | E18: 2 | F18: - | G18: - | H18: - | I18: - | J18: - | K18: - | L18: - | M18: - | N18: - | O18: - | P18: - | Q18: - | R18: - | S18: - | T18: 5 | U18: 5 | V18: 5 | W18: 5 | X18: 5 | Y18: 5 | Z18: 5 | AA18: 5 | AB18: 5 | AC18: 5 | AD18: 5 | AE18: 4 | AF18: 5 | AG18: 5
A19: 17 | B19: AER-1 | C19: M-Y-DP.001 | D19: 5 L KONS. DEZ. DEPO GRUBU | E19: 4 | F19: - | G19: - | H19: - | I19: - | J19: - | K19: - | L19: - | M19: - | N19: - | O19: - | P19: - | Q19: - | R19: - | S19: - | T19: 5 | U19: 5 | V19: 5 | W19: 5 | X19: 5 | Y19: 5 | Z19: 5 | AA19: 5 | AB19: 5 | AC19: 2 | AD19: 5 | AE19: 2 | AF19: 5 | AG19: 2
A20: 18 | B20: AER-1 | C20: M-Y-DP.002 | D20: 5 L ENZİM DEPO GRUBU | E20: 4 | F20: - | G20: - | H20: - | I20: - | J20: - | K20: - | L20: - | M20: - | N20: - | O20: - | P20: - | Q20: - | R20: - | S20: - | T20: 5 | U20: 5 | V20: 5 | W20: 5 | X20: 5 | Y20: 5 | Z20: 5 | AA20: 5 | AB20: 5 | AC20: 2 | AD20: 5 | AE20: 2 | AF20: 5 | AG20: 2
A21: 19 | B21: AER-1 | C21: M-Y-DP.003 | D21: 5 L ALKOL DEPO GRUBU | E21: 4 | F21: - | G21: - | H21: - | I21: - | J21: - | K21: - | L21: - | M21: - | N21: - | O21: - | P21: - | Q21: - | R21: - | S21: - | T21: 5 | U21: 5 | V21: 5 | W21: 5 | X21: 5 | Y21: 5 | Z21: 5 | AA21: 5 | AB21: 5 | AC21: 2 | AD21: 5 | AE21: 2 | AF21: 5 | AG21: 2
A22: 20 | B22: AER-1 | C22: M-Y-DP.005 | D22: 15 L ATIK DEPO GRUBU | E22: 4 | F22: - | G22: - | H22: - | I22: - | J22: - | K22: - | L22: - | M22: - | N22: - | O22: - | P22: - | Q22: - | R22: - | S22: - | T22: 5 | U22: 5 | V22: 5 | W22: 5 | X22: 5 | Y22: 3 | Z22: 5 | AA22: 3 | AB22: 5 | AC22: 2 | AD22: 5 | AE22: 2 | AF22: 5 | AG22: 2
A23: 21 | B23: AER-1 | C23: M-Y-DP.007 | D23: 15 L DEZENFEKTAN DEPO GRUBU | E23: 4 | F23: - | G23: - | H23: - | I23: - | J23: - | K23: - | L23: - | M23: - | N23: - | O23: - | P23: - | Q23: - | R23: - | S23: - | T23: 5 | U23: 5 | V23: 5 | W23: 5 | X23: 5 | Y23: 3 | Z23: 5 | AA23: 3 | AB23: 5 | AC23: 2 | AD23: 5 | AE23: 2 | AF23: 5 | AG23: 2
... A48: 46 | B48: AER-1 | C48: M-Y-MT.003 | D48: SİRKÜLASYON POMPASI GRUBU | E48: 3 | F48: - | G48: - | H48: - | I48: - | J48: - | K48: - | L48: - | M48: - | N48: - | O48: - | P48: - | Q48: - | R48: - | S48: - | T48: 5 | U48: 5 | V48: 5 | W48: 5 | X48: 5 | Y48: 5 | Z48: 5 | AA48: 5 | AB48: 5 | AC48: 5 | AD48: 5 | AE48: 3 | AF48: 5 | AG48: 5
A49: 47 | B49: AER-1 | C49: M-Y-OSB.001 | D49: OSB PAKETLEME | E49: 3 | F49: - | G49: - | H49: - | I49: - | J49: - | K49: - | L49: - | M49: - | N49: - | O49: - | P49: - | Q49: - | R49: - | S49: - | T49: 5 | U49: 3 | V49: 5 | W49: 5 | X49: 5 | Y49: 3 | Z49: - | AA49: - | AB49: - | AC49: - | AD49: - | AE49: - | AF49: 5 | AG49: 5
A50: 48 | B50: AER-1 | C50: M-Y-RG.001 | D50: ATIK MOTOR ÇIKIŞ REKOR GRUBU | E50: 1 | F50: - | G50: - | H50: - | I50: - | J50: - | K50: - | L50: - | M50: - | N50: - | O50: - | P50: - | Q50: - | R50: - | S50: - | T50: 5 | U50: 5 | V50: 5 | W50: 5 | X50: 5 | Y50: 5 | Z50: 5 | AA50: 5 | AB50: 5 | AC50: 5 | AD50: 5 | AE50: 4 | AF50: 5 | AG50: 5
A51: 49 | B51: AER-1 | C51: M-Y-RG.003 | D51: 5 L ENZİM DEPO REKOR GRUBU | E51: 1 | F51: - | G51: - | H51: - | I51: - | J51: - | K51: - | L51: - | M51: - | N51: - | O51: - | P51: - | Q51: - | R51: - | S51: - | T51: 5 | U51: 5 | V51: 5 | W51: 5 | X51: 5 | Y51: 5 | Z51: 5 | AA51: 5 | AB51: 5 | AC51: 5 | AD51: 5 | AE51: 4 | AF51: 5 | AG51: 5
A52: 50 | B52: AER-1 | C52: M-Y-RG.004 | D52: 5 L ALKOL DEPO REKOR GRUBU | E52: 1 | F52: - | G52: - | H52: - | I52: - | J52: - | K52: - | L52: - | M52: - | N52: - | O52: - | P52: - | Q52: - | R52: - | S52: - | T52: 5 | U52: 5 | V52: 5 | W52: 5 | X52: 5 | Y52: 5 | Z52: 5 | AA52: 5 | AB52: 5 | AC52: 5 | AD52: 5 | AE52: 4 | AF52: 5 | AG52: 5
A53: 51 | B53: AER-1 | C53: M-Y-RG.005 | D53: 5 L KONS. DEZ. DEPO REKOR GRUBU | E53: 1 | F53: - | G53: - | H53: - | I53: - | J53: - | K53: - | L53: - | M53: - | N53: - | O53: - | P53: - | Q53: - | R53: - | S53: - | T53: 5 | U53: 5 | V53: 5 | W53: 5 | X53: 5 | Y53: 5 | Z53: 5 | AA53: 5 | AB53: 5 | AC53: 5 | AD53: 5 | AE53: 4 | AF53: 5 | AG53: 5
A54: 52 | B54: AER-1 | C54: M-Y-RG.006 | D54: EVYE DEZENFEKTAN DEPO REKOR GRUBU | E54: 1 | F54: - | G54: - | H54: - | I54: - | J54: - | K54: - | L54: - | M54: - | N54: - | O54: - | P54: - | Q54: - | R54: - | S54: - | T54: 5 | U54: 5 | V54: 5 | W54: 5 | X54: 5 | Y54: 5 | Z54: 5 | AA54: 5 | AB54: 5 | AC54: 5 | AD54: 5 | AE54: 4 | AF54: 5 | AG54: 5
A55: 53 | B55: AER-1 | C55: M-Y-RG.007 | D55: EVYE TEMİZ DEPO REKOR GRUBU | E55: 1 | F55: - | G55: - | H55: - | I55: - | J55: - | K55: - | L55: - | M55: - | N55: - | O55: - | P55: - | Q55: - | R55: - | S55: - | T55: 5 | U55: 5 | V55: 5 | W55: 5 | X55: 5 | Y55: 5 | Z55: 5 | AA55: 5 | AB55: 5 | AC55: 5 | AD55: 5 | AE55: 4 | AF55: 5 | AG55: 5
A56: 54 | B56: AER-1 | C56: M-Y-RK.009 | D56: OTO KAÇAK CPC GRUBU | E56: 5 | F56: - | G56: - | H56: - | I56: - | J56: - | K56: - | L56: - | M56: - | N56: - | O56: - | P56: - | Q56: - | R56: - | S56: - | T56: 5 | U56: 5 | V56: 5 | W56: 5 | X56: 5 | Y56: 5 | Z56: 5 | AA56: 5 | AB56: 5 | AC56: 2 | AD56: 5 | AE56: 4 | AF56: 5 | AG56: 3
A57: 55 | B57: AER-1 | C57: M-Y-RK.010 | D57: HAVA ÇEK-VALFİ | E57: 4 | F57: - | G57: - | H57: - | I57: - | J57: - | K57: - | L57: - | M57: - | N57: - | O57: - | P57: - | Q57: - | R57: - | S57: - | T57: 5 | U57: 5 | V57: 5 | W57: 5 | X57: 5 | Y57: 5 | Z57: 5 | AA57: 5 | AB57: 5 | AC57: 5 | AD57: 5 | AE57: 4 | AF57: 5 | AG57: 5
A58: 56 | B58: AER-1 | C58: M-Y-RK.011 | D58: 1/2 DİK ÇEK-VALF | E58: 5 | F58: - | G58: - | H58: - | I58: - | J58: - | K58: - | L58: - | M58: - | N58: - | O58: - | P58: - | Q58: - | R58: - | S58: - | T58: 5 | U58: 5 | V58: 5 | W58: 5 | X58: 5 | Y58: 5 | Z58: 5 | AA58: 5 | AB58: 5 | AC58: 2 | AD58: 5 | AE58: 2 | AF58: 5 | AG58: 2
A59: 57 | B59: AER-1 | C59: M-Y-5S.013 | D59: SELENOİD GRUBU-ÇİFT SKOP ÇİFT TANK | E59: 5 | F59: - | G59: - | H59: - | I59: - | J59: - | K59: - | L59: - | M59: - | N59: - | O59: - | P59: - | Q59: - | R59: - | S59: - | T59: 5 | U59: 5 | V59: 5 | W59: 5 | X59: 5 | Y59: 5 | Z59: 5 | AA59: 5 | AB59: 5 | AC59: 2 | AD59: 5 | AE59: 2 | AF59: 5 | AG59: 5
A60: 58 | B60: AER-1 | C60: M-Y-AB.004 | D60: EVYE İÇİ PAKET-ÇİFT SCOP | E60: 2 | F60: - | G60: - | H60: - | I60: - | J60: - | K60: - | L60: - | M60: - | N60: - | O60: - | P60: - | Q60: - | R60: - | S60: - | T60: 5 | U60: 3 | V60: 5 | W60: 5 | X60: 5 | Y60: 3 | Z60: 5 | AA60: 5 | AB60: 5 | AC60: 5 | AD60: 5 | AE60: 3 | AF60: 5 | AG60: 3
A61: 59 | B61: AER-1 | C61: M-Y-SG.001 | D61: SU GİRİŞ VENTİLİ GRUBU | E61: 4 | F61: - | G61: - | H61: - | I61: - | J61: - | K61: - | L61: - | M61: - | N61: - | O61: - | P61: - | Q61: - | R61: - | S61: - | T61: 5 | U61: 5 | V61: 5 | W61: 5 | X61: 5 | Y61: 5 | Z61: 5 | AA61: 5 | AB61: 5 | AC61: 5 | AD61: 5 | AE61: 4 | AF61: 5 | AG61: 5
... A65: 63 | B65: AER-1 | C65: M-Y-ÜS.001 | D65: ÜST SENSÖR GRUBU | E65: 2 | F65: - | G65: - | H65: - | I65: - | J65: - | K65: - | L65: - | M65: - | N65: - | O65: - | P65: - | Q65: - | R65: - | S65: - | T65: 5 | U65: 5 | V65: 5 | W65: 5 | X65: 5 | Y65: 5 | Z65: 5 | AA65: 5 | AB65: 5 | AC65: 5 | AD65: 5 | AE65: 4 | AF65: 5 | AG65: 5
A66: 64 | B66: AER-3 | C66: AER-3 | D66: AER-3 MONTAJ HATTI 1 | E66: 4 | F66: 5 | G66: 4 | H66: 5 | I66: 2 | J66: 5 | K66: 5 | L66: 5 | M66: 5 | N66: - | O66: - | P66: 5 | Q66: 4 | R66: 5 | S66: 5 | T66: - | U66: - | V66: - | W66: - | X66: - | Y66: - | Z66: - | AA66: - | AB66: - | AC66: - | AD66: - | AE66: - | AF66: - | AG66: -
A67: 65 | B67: AER-3 | C67: AER-3 | D67: AER-3 MONTAJ HATTI 2 | E67: 4 | F67: 5 | G67: 4 | H67: 5 | I67: 2 | J67: 5 | K67: 5 | L67: 5 | M67: 5 | N67: - | O67: - | P67: 5 | Q67: 4 | R67: 5 | S67: 5 | T67: - | U67: - | V67: - | W67: - | X67: - | Y67: - | Z67: - | AA67: - | AB67: - | AC67: - | AD67: - | AE67: - | AF67: - | AG67: -
...

Sheet Değer Matrisleri
B5: Değer | C5: Puan | G5: Puan | H5: Açıklama
B6: Çok İyi | C6: 5 | G6: 5 | H6: Görevi tamamen bağımsız, hatasız ve standart sürenin altında gerçekleştirir. Karmaşık ayarları/şartlandırmaları yapabilir. Problemleri analiz eder, kök neden bularak çözüm üretir. Gerektiğinde başkalarına eğitim verebilir.
B7: İyi | C7: 4 | G7: 4 | H7: Görevi çoğunlukla bağımsız gerçekleştirir. Nadiren destek ihtiyacı duyar. Ayar ve bağlantıları doğru yapar, küçük problemleri kendi başına çözer. Standartlara uygundur.
B8: Orta | C8: 3 | G8: 3 | H8: Görevi talimat ve iş emri doğrultusunda gerçekleştirir. Zaman zaman destek alır. Standart sürede çalışır ancak ayar/ince hassasiyet gerektiren durumlarda yönlendirmeye ihtiyaç duyar.
B9: Gelişime Açık | C9: 2 | G9: 2 | H9: Görevi sürekli destek ve yönlendirme ile yapabilir. Hata yapma riski yüksektir. Standart sürelerin üzerindedir, ayar ve kontrol adımlarını tek başına yönetemez.
B10: Düşük | C10: 1 | G10: 1 | H10: Görevi tek başına yapamaz. Süreç bilgisi ve uygulama yetkinliği yoktur. Eğitim alması ve gözetim altında çalışması gerekir.
B12: Değer | C12: Puan | G12: Puan | H12: Açıklama
B13: Çok Zor | C13: 5 | G13: 5 | H13: Yüksek teknik bilgi ve deneyim gerektirir. Birden fazla sistemin (mekanik, elektronik, pnömatik vb.) aynı anda yönetilmesini, hassas ayar ve karar vermeyi içerir. Hata riski yüksektir ve sonuçları kritiktir.
B14: Zor | C14: 4 | G14: 4 | H14: Teknik bilgi gerektirir. Birden fazla işlem adımı ve kontrol noktası vardır. Ayar ve doğrulama gerektirir, dikkat ve deneyim olmazsa hata riski oluşur.
B15: Orta | C15: 3 | G15: 3 | H15: Standart iş talimatı ile yapılabilir. İşlem adımları nettir ancak dikkat ve temel teknik bilgi gerektirir. Hata riski orta seviyededir.
B16: Kolay | C16: 2 | G16: 2 | H16: Tekrarlı ve basit işlem adımlarından oluşur. Kısa sürede öğrenilebilir. Özel teknik bilgi veya ayar gerektirmez.
B17: Çok Kolay | C17: 1 | G17: 1 | H17: Fiziksel veya görsel kontrol ağırlıklıdır. Eğitim ihtiyacı çok düşüktür. Hata riski düşüktür ve işlem adımları son derece basittir.

Sheet Menü Seçenekleri
B5: MENÜ SEÇENEKLERİ
B7: CİHAZ | D7: OPERASYON-YM ADI | F7: PERSONELLER | G7: PERSONELLER
B8: AER-1 | D8: AER-1 MONTAJ HATTI 1 | F8: İZZET ATAKAN DEMİR | G8: İZZET ATAKAN DEMİR (H)
B9: AER-3 | D9: AER-1 MONTAJ HATTI 2 | F9: ÜMİT UZUN | G9: ÜMİT UZUN (H)
B10: DSC-1201 | D10: AER-1 MONTAJ HATTI 3 | F10: TOLGAHAN ÇEBİ | G10: TOLGAHAN ÇEBİ (H)
B11: MAKDA9004-01 | D11: AER-1 MONTAJ HATTI 4 | F11: KAĞAN UDUM | G11: KAĞAN UDUM (H)
D12: AER-1 5 YIKAMA HAZIRLIK | F12: OZAN HATAY | G12: OZAN HATAY (H)
D13: AER-1 YIKAMA HATTI REWORK | F13: ÖZER KOÇ | G13: ÖZER KOÇ (H)
D14: AER-1 TEMİZLİK HATTI | F14: ÖMER POLAT | G14: ÖMER POLAT (H)
D15: AER-1 PAKET ÖNCESİ HAZIRLIK | F15: SEMRA ULTAV | G15: SEMRA ULTAV (H)
D16: AER-1 PAKETLEME OPERASYONU | F16: HANDE GÜNAYDIN | G16: HANDE GÜNAYDIN (H)
D17: CPC ERKEK 90° | F17: MUSA HIZIR | G17: MUSA HIZIR (H)
D18: DIŞ FİLTRE GRUBU | F18: VOLKAN KAVLAK | G18: VOLKAN KAVLAK (H)
D19: CPC DAĞITICI-ÇİFT SKOP GRUBU | F19: SULTAN SOLAK | G19: SULTAN SOLAK (H)
D20: NOZZLE DAĞITICI GRUBU | F20: EMİR KODAŞ | G20: EMİR KODAŞ (H)
D21: DOLUM KAPAK GRUBU-ALKOL | F21: MURAT KİRAZ | G21: MURAT KİRAZ (H)
D22: DOLUM KAPAK GRUBU-ENZIMATIK
D23: DOLUM KAPAK GRUBU-KONSANTRE
D24: 5 L KONS. DEZ. DEPO GRUBU
D25: 5 L ENZİM DEPO GRUBU
D26: 5 L ALKOL DEPO GRUBU
D27: 15 L ATIK DEPO GRUBU
D28: 15 L DEZENFEKTAN DEPO GRUBU
D29: 15 L TEMİZ SU DEPO GRUBU
D30: 15 L PASLANMAZ DEPO GRUBU
D31: DOZAJ POMPA GRUBU 7 L
D32: 70X100 TANITIM PLAKASI
D33: GİRDAP ÖNLEYİCİ
... D173: DETROAIR SPREY ÖN PANEL GRUBU

Sheet Pivot
A3: STOK KODU | B3: STOK ADI | C3: Toplam M.FURKAN YAVUZ | D3: Toplam KAĞAN UDUM | E3: Toplam İZZET ATAKAN DEMİR | F3: Toplam MEHMET KAPLAN | G3: Toplam TOLGAHAN ÇEBİ | H3: Toplam ÖZER KOÇ | I3: Toplam VOLKAN KAVLAK | J3: Toplam HANDE GÜNAYDIN | K3: Toplam SEMRA ULTAV | L3: Toplam SULTAN SOLAK | M3: Toplam MUSA HIZIR | N3: Toplam ÖMER POLAT
A4: AER-1 | B4: AER-1 5 YIKAMA HAZIRLIK | C4: 5 | D4: 5 | E4: 2 | F4: 1 | G4: 1 | H4: 1 | I4: 4 | J4: 1 | K4: 1 | L4: 1 | M4: 1 | N4: 1
B5: AER-1 MONTAJ HATTI 1 | C5: 5 | D5: 5 | E5: 4 | F5: 4 | G5: 4 | H5: 2 | I5: 5 | J5: 1 | K5: 1 | L5: 1 | M5: 1 | N5: 1
B6: AER-1 MONTAJ HATTI 2 | C6: 5 | D6: 5 | E6: 4 | F6: 4 | G6: 4 | H6: 2 | I6: 5 | J6: 1 | K6: 1 | L6: 1 | M6: 1 | N6: 1
B7: AER-1 MONTAJ HATTI 3 | C7: 5 | D7: 5 | E7: 3 | F7: 2 | G7: 4 | H7: 2 | I7: 5 | J7: 1 | K7: 1 | L7: 1 | M7: 1 | N7: 1
B8: AER-1 MONTAJ HATTI 4 | C8: 5 | D8: 5 | E8: 3 | F8: 2 | G8: 4 | H8: 2 | I8: 5 | J8: 1 | K8: 1 | L8: 1 | M8: 1 | N8: 1
B9: AER-1 PAKET ÖNCESİ HAZIRLIK | C9: 4 | D9: 5 | E9: 3 | F9: 1 | G9: 3 | H9: 3 | I9: 5 | J9: 1 | K9: 1 | L9: 1 | M9: 1 | N9: 1
B10: AER-1 PAKETLEME OPERASYONU | C10: 5 | D10: 5 | E10: 5 | F10: 3 | G10: 3 | H10: 5 | I10: 5 | J10: 1 | K10: 1 | L10: 1 | M10: 3 | N10: 3
B11: AER-1 TEMİZLİK HATTI | C11: 3 | D11: 3 | E11: 3 | F11: 3 | G11: 3 | H11: 3 | I11: 3 | J11: 5 | K11: 5 | L11: 5 | M11: 3 | N11: 3 | P11: {=yatay} -> #NAME?
B12: AER-1 YIKAMA HATTI REWORK | C12: 5 | D12: 5 | E12: 4 | F12: 4 | G12: 4 | H12: 4 | I12: 5 | J12: 1 | K12: 1 | L12: 1 | M12: 1 | N12: 1
A13: AER-3 | B13: AER-3 5 YIKAMA HAZIRLIK | C13: 5 | D13: 5 | E13: 2 | F13: 1 | G13: 1 | H13: 2 | I13: 4 | J13: 1 | K13: 1 | L13: 1 | M13: 1 | N13: 1
B14: AER-3 MONTAJ HATTI 1 | C14: 5 | D14: 5 | E14: 4 | F14: 4 | G14: 5 | H14: 2 | I14: 5 | J14: 1 | K14: 1 | L14: 1 | M14: 1 | N14: 1
B15: AER-3 MONTAJ HATTI 2 | C15: 5 | D15: 5 | E15: 4 | F15: 4 | G15: 5 | H15: 2 | I15: 5 | J15: 1 | K15: 1 | L15: 1 | M15: 1 | N15: 1
B16: AER-3 MONTAJ HATTI 3 | C16: 5 | D16: 5 | E16: 3 | F16: 2 | G16: 5 | H16: 2 | I16: 5 | J16: 1 | K16: 1 | L16: 1 | M16: 1 | N16: 1
B17: AER-3 MONTAJ HATTI 4 | C17: 5 | D17: 5 | E17: 3 | F17: 2 | G17: 5 | H17: 2 | I17: 5 | J17: 1 | K17: 1 | L17: 1 | M17: 1 | N17: 1
B18: AER-3 PAKET ÖNCESİ HAZIRLIK | C18: 4 | D18: 5 | E18: 3 | F18: 1 | G18: 3 | H18: 3 | I18: 5 | J18: 1 | K18: 1 | L18: 1 | M18: 1 | N18: 1
B19: AER-3 PAKETLEME OPERASYONU | C19: 5 | D19: 5 | E19: 5 | F19: 3 | G19: 3 | H19: 5 | I19: 5 | J19: 1 | K19: 1 | L19: 1 | M19: 3 | N19: 3
B20: AER-3 TEMİZLİK HATTI | C20: 3 | D20: 3 | E20: 3 | F20: 3 | G20: 3 | H20: 3 | I20: 3 | J20: 5 | K20: 5 | L20: 5 | M20: 3 | N20: 3
B21: AER-3 YIKAMA HATTI REWORK | C21: 5 | D21: 5 | E21: 4 | F21: 4 | G21: 4 | H21: 4 | I21: 5 | J21: 1 | K21: 1 | L21: 1 | M21: 1 | N21: 1
A22: DSC-1201 | B22: DSC FİNAL KONTROL OPERASYONU | C22: 1 | D22: 1 | E22: 1 | F22: 1 | G22: 1 | H22: 1 | I22: 5 | J22: 1 | K22: 1 | L22: 2 | M22: 1 | N22: 1
B23: DSC MONTAJ OPERASYONU | C23: 1 | D23: 1 | E23: 1 | F23: 1 | G23: 1 | H23: 1 | I23: 5 | J23: 1 | K23: 1 | L23: 2 | M23: 1 | N23: 1
B24: DSC PAKETLEME OPERASYONU | C24: 5 | D24: 5 | E24: 5 | F24: 3 | G24: 3 | H24: 5 | I24: 5 | J24: 1 | K24: 1 | L24: 1 | M24: 3 | N24: 3
B25: DSC TEMİZLİK OPERASYONU | C25: 2 | D25: 2 | E25: 2 | F25: 2 | G25: 2 | H25: 2 | I25: 5 | J25: 3 | K25: 4 | L25: 4 | M25: 3 | N25: 3
A26: MAKDA9004-01 | B26: MAKDA9004-01 - MONTAJ OPERASYONU | C26: 2 | D26: 3 | E26: 3 | F26: 3 | G26: 3 | H26: 3 | I26: 5 | J26: 3 | K26: 3 | L26: 2 | M26: 4 | N26: 3
B27: MAKDA9004-01 - PAKETLEME OPERASYONU | C27: 2 | D27: 3 | E27: 3 | F27: 3 | G27: 3 | H27: 5 | I27: 5 | J27: 4 | K27: 4 | L27: 4 | M27: 4 | N27: 3
B28: MAKDA9004-01 - TEMİZLİK OPERASYONU | C28: 3 | D28: 3 | E28: 3 | F28: 3 | G28: 3 | H28: 3 | I28: 5 | J28: 4 | K28: 4 | L28: 4 | M28: 4 | N28: 3
A29: M-DA-Y-BG.001 | B29: DETROAIR SPREY BAŞLIK YUVA GRUBU | C29: 2 | D29: 2 | E29: 2 | F29: 2 | G29: 2 | H29: 4 | I29: 5 | J29: 3 | K29: 3 | L29: 3 | M29: 4 | N29: 3
A30: M-DA-Y-KS.002 | B30: DETROAIR SPREY KASA MONTAJ GRUBU | C30: 2 | D30: 2 | E30: 2 | F30: 2 | G30: 2 | H30: 4 | I30: 5 | J30: 3 | K30: 3 | L30: 3 | M30: 4 | N30: 3
A31: M-DA-Y-KS.003 | B31: BAŞLIK GRUBU | C31: 2 | D31: 2 | E31: 2 | F31: 2 | G31: 2 | H31: 5 | I31: 5 | J31: 4 | K31: 3 | L31: 3 | M31: 4 | N31: 3
A32: M-DA-Y-MT.001 | B32: DETROAIR SPREY MOTOR GRUBU | C32: 2 | D32: 2 | E32: 2 | F32: 2 | G32: 2 | H32: 4 | I32: 5 | J32: 3 | K32: 3 | L32: 3 | M32: 4 | N32: 3
A33: M-DA-Y-PN.001 | B33: DETROAIR SPREY ÖN PANEL GRUBU | C33: 2 | D33: 2 | E33: 2 | F33: 2 | G33: 2 | H33: 4 | I33: 5 | J33: 3 | K33: 3 | L33: 3 | M33: 4 | N33: 3
A34: M-DS-Y-AG.001 | B34: ASKI GRUBU | C34: 2 | D34: 2 | E34: 2 | F34: 2 | G34: 2 | H34: 5 | I34: 5 | J34: 3 | K34: 3 | L34: 3 | M34: 3 | N34: 3
A35: M-DS-Y-AS.005 | B35: PLUG FAN GRUBU | C35: 2 | D35: 2 | E35: 2 | F35: 2 | G35: 2 | H35: 5 | I35: 5 | J35: 3 | K35: 3 | L35: 3 | M35: 3 | N35: 3
A36: M-DS-Y-GKG.001 | B36: GÜÇ KABLOSU GRUBU | C36: 2 | D36: 2 | E36: 2 | F36: 2 | G36: 2 | H36: 5 | I36: 5 | J36: 3 | K36: 3 | L36: 3 | M36: 3 | N36: 3
A37: M-DS-Y-HV.001 | B37: 5 L PASLANMAZ HAVA TANK GRUBU | C37: 2 | D37: 2 | E37: 2 | F37: 2 | G37: 2 | H37: 5 | I37: 5 | J37: 3 | K37: 3 | L37: 3 | M37: 4 | N37: 4
A38: M-DS-Y-KKG.001 | B38: SELENOİD KİLİT GRUBU | C38: 2 | D38: 2 | E38: 2 | F38: 2 | G38: 2 | H38: 5 | I38: 5 | J38: 3 | K38: 3 | L38: 3 | M38: 3 | N38: 3
A39: M-DS-Y-KM.001 | B39: DSC KOMPRESÖR GRUBU 50HZ | C39: 2 | D39: 2 | E39: 1 | F39: 1 | G39: 1 | H39: 5 | I39: 5 | J39: 3 | K39: 3 | L39: 3 | M39: 4 | N39: 4
A40: M-DS-Y-KM.003 | B40: DSC KOMPRESÖR BASINÇ ŞALTER GRUBU | C40: 2 | D40: 2 | E40: 2 | F40: 2 | G40: 2 | H40: 5 | I40: 5 | J40: 4 | K40: 4 | L40: 4 | M40: 4 | N40: 4
... A165: M-Y-ÜS.001 | B165: ÜST SENSÖR GRUBU | C165: 3 | D165: 3 | E165: 3 | F165: 3 | G165: 3 | H165: 5 | I165: 4 | J165: 4 | K165: 4 | L165: 4 | M165: 4 | N165: 4
A166: Genel Toplam | C166: 511 | D166: 458 | E166: 427 | F166: 409 | G166: 425 | H166: 735 | I166: 669 | J166: 500 | K166: 551 | L166: 506 | M166: 546 | N166: 559

Sheet Personel Görev Dağılım
B1: DETROX CİHAZ MONTAJ PERSONEL GÖREV DAĞILIM LİSTESİ DEVICE ASSEMBLY STAFF DUTY ASSIGNMENT LIST | E1: Doküman No. Document Nu.
E2: Yayın Tarihi Publication Date
E3: Revizyon No. Revision Nu.
E4: Revizyon Tarihi Revision Date
A5: ADI SOYADI NAME & SURNAME | B5: ANA GÖREV MAIN DUTY | C5: YAN GÖREV SECOND DUTY | D5: KADRO ÜNVANI JOB TITLE | E5: OLMADIĞINDA YERİNE BAKACAK KİŞİ ALTERNATE | F5: YETKİLİSİ SUPERVISOR
A6: HANDE GÜNAYDIN | B6: TEMİZLİK | C6: YARI MAMUL MONTAJ | D6: YARI MAMUL MONTAJ OP. | E6: SULTAN SOLAK | F6: ÖZER KOÇ
A7: İZZET ATAKAN DEMİR | B7: ANA MONTAJ | C7: FİNAL KALİTE KONTROL HAZIRLIK | D7: ANA MONTAJ OP. | E7: TOLGAHAN ÇEBİ | F7: TOLGAHAN ÇEBİ
A8: KAĞAN UDUM | B8: FİNAL KALİTE KONTROL HAZIRLIK | C8: 5 YIKAMA TESTİ | D8: SEVK HAZIRLIK SORUMLUSU | E8: VOLKAN KAVLAK | F8: ÖMER POLAT
A9: MUHAMMED FURKAN YAVUZ | B9: 5 YIKAMA TESTİ | C9: FİNAL KALİTE KONTROL HAZIRLIK | D9: MONTAJ TEST OP. | E9: OZAN HATAY | F9: ÖMER POLAT
A10: MUSA HIZIR | B10: YARI MAMUL MONTAJ | C10: DETRO AIR SPRAY MONTAJ | D10: DAS SORUMLUSU | E10: EMİR KADAŞ | F10: ÖMER POLAT
A11: ÖMER POLAT | B11: YARI MAMUL MONTAJ | C11: LAZER MAKİNESİ | D11: SUPERVISOR | E11: ÖZER KOÇ | F11: GÖKTUĞ ERGİN
A12: ÖZER KOÇ | B12: YARI MAMUL MONTAJ | C12: CİHAZ KALİBRASYON | D12: YARIMAMUL SORUMLUSU | E12: ÖMER POLAT | F12: ÖMER POLAT
A13: SEMRA ULTAV | B13: KAPAK YARI MAMUL MONTAJ | C13: YARI MAMUL MONTAJ | D13: YARI MAMUL MONTAJ OP. | E13: ÖZER KOÇ | F13: ÖZER KOÇ
A14: SULTAN SOLAK | B14: EVYE YARI MAMUL MONTAJ | C14: YARI MAMUL MONTAJ | D14: YARI MAMUL MONTAJ OP. | E14: VOLKAN KAVLAK | F14: ÖZER KOÇ
A15: TOLGAHAN ÇEBİ | B15: ANA MONTAJ | C15: DETRO AIR SPRAY MONTAJ | D15: ANA MONTAJ SORUMLUSU | E15: İZZET AKDEMİR | F15: GÖKTUĞ ERGİN
A16: VOLKAN KAVLAK | B16: DSC MONTAJ | C16: 5 YIKAMA TESTİ | D16: DSC SORUMLUSU | E16: KAĞAN UDUM | F16: ÖMER POLAT
... A18: MURAT KİRAZ | B18: ANA MONTAJ | C18: 5 YIKAMA TESTİ | D18: ANA MONTAJ OP. | E18: ÜMİT UYGUN | F18: TOLGAHAN ÇEBİ
A19: ÜMİT UZUN | B19: ANA MONTAJ | D19: ANA MONTAJ OP. | E19: MURAT KİRAZ | F19: TOLGAHAN ÇEBİ
A20: OZAN HATAY | B20: 5 YIKAMA TESTİ | C20: FİNAL KALİTE KONTROL HAZIRLIK | D20: MONTAJ TEST OP. | E20: MUHAMMED FURKAN YAVUZ | F20: ÖMER POLAT

Sheet Niş Bölünmeler
A1: BÖLÜM | B1: PERSONEL ADI
A2: MONTAJ HATTI PERSONELLERİ | B2: İZZET ATAKAN DEMİR
B3: MEHMET KAPLAN
B4: TOLGAHAN ÇEBİ
B5: KAĞAN UDUM
A6: MONTAJ TEST PERSONELLERİ | B6: M.FURKAN YAVUZ
B7: KAĞAN UDUM
A8: MONTAJ TEST SONRASI PERSONELLERİ | B8: VOLKAN KAVLAK
B9: KAĞAN UDUM
A10: YM MONTAJ PERSONELLERİ | B10: ÖZER KOÇ
B11: ÖMER POLAT
B12: SEMRA ULTAV
B13: HANDE GÜNAYDIN
B14: MUSA HIZIR
B15: SULTAN SOLAK
A16: DSC MONTAJ PERSONELLERİ | B16: VOLKAN KAVLAK
A17: DAS MONTAJ PERSONELLERİ | B17: VOLKAN KAVLAK
B18: MUSA HIZIR
B19: SEMRA ULTAV
B20: HANDE GÜNAYDIN
A21: AER 1 KAPAK PERSONELLERİ | B21: SEMRA ULTAV
A22: AER 3 KAPAK PERSONELLERİ | B22: ÖZER KOÇ
B23: MUSA HIZIR
A24: AER 1 EVYE PERSONELLERİ | B24: VOLKAN KAVLAK
B25: SULTAN SOLAK
A26: AER 3 EVYE PERSONELLERİ | B26: VOLKAN KAVLAK
B27: SULTAN SOLAK
